---
id: 6733bee844600f35c05b8264
title: '¿Cómo funciona try...catch...finally?'
challengeType: 11
videoId: _3whfUfxGYI
dashedName: how-does-try-catch-finally-work
---

# --description--

Mira el video o lee la transcripción y responde a las preguntas a continuación.

# --transcript--

¿Cómo funciona `try…catch…finally`?

En el video de la conferencia anterior, aprendiste a lanzar excepciones en tus programas. En este video de la conferencia, echaremos un vistazo a cómo manejar estos errores de manera elegante en un bloque `try…catch…finally`.

El bloque `try` se utiliza para envolver código que podría generar un error. Actúa como un espacio seguro para intentar algo que podría fallar.

El bloque `catch` captura y maneja errores que ocurren en el bloque `try`. Puedes usar el objeto `Error` dentro de `catch` para inspeccionar qué salió mal.

El bloque `finally` se ejecuta después de los bloques `try` y `catch`, independientemente de si ocurrió un error. Comúnmente, se utiliza para tareas de limpieza, como cerrar archivos o liberar recursos.

Aquí hay un ejemplo de uso de un bloque `try…catch`:

```js
function processInput(input) {
  if (typeof input !== "string") {
    throw new TypeError("Input must be a string.");
  }

  return input.toUpperCase();
}

try {
  console.log("Starting to process input...");
  const result = processInput(9);
  console.log("Processed result:", result);
} catch (error) {
  console.error("Error occurred:", error.message);
} 
```

En este ejemplo, tenemos una función llamada `processInput` que primero verifica si el `input` no es del tipo `cadena`. Si ese es el caso, entonces lanzamos un error. De lo contrario, devolvemos el resultado de usar el método `toUpperCase` en el `input`.

Llamamos a la función dentro de un bloque `try`. Dado que la llamada a la función lanza un error, entonces será capturado dentro del bloque `catch` y el mensaje de error se mostrará en la consola.

El error pasado al bloque `catch` es un objeto `Error` que contiene información sobre ese error. En este caso, estamos utilizando la propiedad `message` que muestra información legible por humanos al usuario.

Estamos utilizando `console.error` porque está diseñado específicamente para registrar errores. En muchos navegadores modernos, la salida de `console.error()` aparece en rojo en la consola.

El enunciado `finally` se ejecuta independientemente de si se lanzó o no una excepción.

```js
try {
  // Code that might throw an error
} catch (error) {
  // Code to handle the error
} finally {
  // Code that runs regardless of whether an error occurred or not
}
```

Un buen caso de uso para el enunciado `finally` es si estuvieras trabajando con archivos. En JavaScript, puedes abrir un archivo, utilizar un bloque `try` para escribir datos en el archivo. Si hay algún error, puedes usar el `catch` para capturar esos errores. Luego usa el enunciado `finally` para cerrar el archivo.

# --questions--

## --text--

¿Qué describe mejor el bloque `try`?

## --answers--

Es para ejecutar el código nuevamente automáticamente después de que ocurra un error.

### --feedback--

Piense en el orden de los bloques en los enunciados `try…catch…finally`, y los tipos de tareas que maneja cada bloque.

---

Es para manejar errores.

### --feedback--

Piense en el orden de los bloques en los enunciados `try…catch…finally`, y los tipos de tareas que maneja cada bloque.

---

Es para preparar antes de que se genere un error.

### --feedback--

Piense en el orden de los bloques en los enunciados `try…catch…finally`, y los tipos de tareas que maneja cada bloque.

---

Es un envoltorio seguro para código que podría generar un error.

## --video-solution--

4

## --text--

¿Qué bloque siempre se ejecuta incluso si ocurre un error?

## --answers--

`try`

### --feedback--

Este bloque se utiliza a menudo para tareas de limpieza.

---

`catch`

### --feedback--

Este bloque se utiliza a menudo para tareas de limpieza.

---

`finally`

---

`throw`

### --feedback--

Este bloque se utiliza a menudo para tareas de limpieza.

## --video-solution--

3

## --text--

¿Cuál es el propósito del bloque `catch`?

## --answers--

Para ejecutar código que podría generar un error.

### --feedback--

Este bloque se activa cuando algo sale mal en el bloque `try`.

---

Para definir un espacio seguro para la ejecución de código.

### --feedback--

Este bloque se activa cuando algo sale mal en el bloque `try`.

---

Para manejar errores de manera elegante sin bloquear el programa.

---

Para ejecutarse siempre, independientemente de los errores.

### --feedback--

Este bloque se activa cuando algo sale mal en el bloque `try`.

## --video-solution--

3
